2024-03-03 13:49:12,100 Start MPyC runtime v0.9
2024-03-03 13:49:12,131 Start MPyC runtime v0.9
2024-03-03 13:49:12,247 All 2 parties connected.
Give your input here: here's your payload:  F4C8U5KWVPHI7VTSTI2EAWMHNVZP8EWP3
The given input is a message!
Give the other input here: 2024-03-03 13:49:12,250 All 2 parties connected.
Give your input here: here's your payload:  (b'KUY0U0WI06B66JP1JI13P2X9TZFEVQ1Hx9exdf-"x14x9bxf7xcfx18xfcxa5xcexf4x05x85lgC3xaex89xdetxebfxba|`x90"xfax0f', b'I49YYV7LDGEC85QCFVJUTPNRYR2IX2CLE4OE8JEMTOV3VB12NZENGODWENU6Q4SKKUY0U0WI06B66JP1JI13P2X9TZFEVQ1Hx9exdf-"x14x9bxf7xcfx18xfcxa5xcexf4x05x85lgC3xaex89xdetxebfxba|`x90"xfax0f')
The given input is a secret key!
Give the other input here: here's the payload:  [<mpyc.sectypes.ArraySecFld1(GF(2)) object at 0x7fce171a79a0>, <mpyc.sectypes.ArraySecFld1(GF(2)) object at 0x7fce171a7880>, <mpyc.sectypes.ArraySecFld1(GF(2)) object at 0x7fce106bb760>, <mpyc.sectypes.ArraySecFld1(GF(2)) object at 0x7fce106bb700>]
here's the inputs:  [[<mpyc.sectypes.ArraySecFld1(GF(2)) object at 0x7fce106bb7f0>, <mpyc.sectypes.ArraySecFld1(GF(2)) object at 0x7fce106bb850>, <mpyc.sectypes.ArraySecFld1(GF(2)) object at 0x7fce106bb880>, <mpyc.sectypes.ArraySecFld1(GF(2)) object at 0x7fce106bb8b0>], [<mpyc.sectypes.ArraySecFld1(GF(2)) object at 0x7fce106bb820>, <mpyc.sectypes.ArraySecFld1(GF(2)) object at 0x7fce106bb910>, <mpyc.sectypes.ArraySecFld1(GF(2)) object at 0x7fce106bb940>, <mpyc.sectypes.ArraySecFld1(GF(2)) object at 0x7fce106bb970>]]

Signing process begins now...
The length of the message and secret key is wrong! Please restart the function!
2024-03-03 13:49:13,669 Unhandled exception in event loop
Traceback (most recent call last):
  File "/home/codespace/.python/current/lib/python3.10/asyncio/events.py", line 80, in _run
    self._context.run(self._callback, *self._args)
  File "/home/codespace/.python/current/lib/python3.10/site-packages/mpyc/asyncoro.py", line 431, in <lambda>
    task.add_done_callback(lambda t: _reconcile(decl, t))
  File "/home/codespace/.python/current/lib/python3.10/site-packages/mpyc/asyncoro.py", line 355, in _reconcile
    givn = task.result()
  File "/home/codespace/.python/current/lib/python3.10/site-packages/mpyc/asyncoro.py", line 283, in _wrap_in_coro
    return await awaitable
  File "/home/codespace/.python/current/lib/python3.10/site-packages/mpyc/asyncoro.py", line 271, in __await__
    val = self.coro.send(None)
  File "/home/codespace/.python/current/lib/python3.10/site-packages/mpyc/runtime.py", line 452, in _distribute
    y = [[field.array(unmarshal(r), check=False).reshape(shape) for r in shares]]
  File "/home/codespace/.python/current/lib/python3.10/site-packages/mpyc/runtime.py", line 452, in <listcomp>
    y = [[field.array(unmarshal(r), check=False).reshape(shape) for r in shares]]
  File "/home/codespace/.python/current/lib/python3.10/site-packages/mpyc/finfields.py", line 1289, in reshape
    return type(self)(self.value.reshape(*args, **kwargs), check=False)
ValueError: cannot reshape array of size 264 into shape (256,)
Traceback (enclosing MPyC coroutine call):
here's the payload:  [<mpyc.sectypes.ArraySecFld1(GF(2)) object at 0x7fcf064a79a0>, <mpyc.sectypes.ArraySecFld1(GF(2)) object at 0x7fceff9b1f00>, <mpyc.sectypes.ArraySecFld1(GF(2)) object at 0x7fceff9b1fc0>, <mpyc.sectypes.ArraySecFld1(GF(2)) object at 0x7fceff9b3730>]
here's the inputs:  [[<mpyc.sectypes.ArraySecFld1(GF(2)) object at 0x7fceff9b39d0>, <mpyc.sectypes.ArraySecFld1(GF(2)) object at 0x7fceff9b3fd0>, <mpyc.sectypes.ArraySecFld1(GF(2)) object at 0x7fceff9b3970>, <mpyc.sectypes.ArraySecFld1(GF(2)) object at 0x7fceff9b39a0>], [<mpyc.sectypes.ArraySecFld1(GF(2)) object at 0x7fceff9b3e80>, <mpyc.sectypes.ArraySecFld1(GF(2)) object at 0x7fceff764040>, <mpyc.sectypes.ArraySecFld1(GF(2)) object at 0x7fceff7640a0>, <mpyc.sectypes.ArraySecFld1(GF(2)) object at 0x7fceff7640d0>]]

Signing process begins now...
The length of the message and secret key is wrong! Please restart the function!
2024-03-03 13:49:13,666 Unhandled exception in event loop
Traceback (most recent call last):
  File "/home/codespace/.python/current/lib/python3.10/asyncio/events.py", line 80, in _run
    self._context.run(self._callback, *self._args)
  File "/home/codespace/.python/current/lib/python3.10/site-packages/mpyc/asyncoro.py", line 431, in <lambda>
    task.add_done_callback(lambda t: _reconcile(decl, t))
  File "/home/codespace/.python/current/lib/python3.10/site-packages/mpyc/asyncoro.py", line 355, in _reconcile
    givn = task.result()
  File "/home/codespace/.python/current/lib/python3.10/site-packages/mpyc/asyncoro.py", line 283, in _wrap_in_coro
    return await awaitable
  File "/home/codespace/.python/current/lib/python3.10/site-packages/mpyc/asyncoro.py", line 271, in __await__
    val = self.coro.send(None)
  File "/home/codespace/.python/current/lib/python3.10/site-packages/mpyc/runtime.py", line 452, in _distribute
    y = [[field.array(unmarshal(r), check=False).reshape(shape) for r in shares]]
  File "/home/codespace/.python/current/lib/python3.10/site-packages/mpyc/runtime.py", line 452, in <listcomp>
    y = [[field.array(unmarshal(r), check=False).reshape(shape) for r in shares]]
  File "/home/codespace/.python/current/lib/python3.10/site-packages/mpyc/finfields.py", line 1289, in reshape
    return type(self)(self.value.reshape(*args, **kwargs), check=False)
ValueError: cannot reshape array of size 256 into shape (264,)
Traceback (enclosing MPyC coroutine call):
