Success
2024-02-18 01:59:30,466 Start MPyC runtime v0.9.8
2024-02-18 01:59:30,470 Start MPyC runtime v0.9.8
2024-02-18 01:59:30,474 All 2 parties connected.
Give your input here: 2024-02-18 01:59:30,474 All 2 parties connected.
Give your input here: here's your payload:  1PXZ79KCLKW20AAM0202GUW58XSXOO1BPUBW8EVBGXWYKFZ6GHC3RNP01G7X7S
The given input is a message!
here's the payload:  [<mpyc.sectypes.ArraySecFld1(GF(2)) object at 0x7fca63f5fb50>, <mpyc.sectypes.ArraySecFld1(GF(2)) object at 0x7fca583e2f50>, <mpyc.sectypes.ArraySecFld1(GF(2)) object at 0x7fca583e2fb0>, <mpyc.sectypes.ArraySecFld1(GF(2)) object at 0x7fca583e3100>]
here's the inputs:  [[<mpyc.sectypes.ArraySecFld1(GF(2)) object at 0x7fca584152d0>, <mpyc.sectypes.ArraySecFld1(GF(2)) object at 0x7fca58415300>, <mpyc.sectypes.ArraySecFld1(GF(2)) object at 0x7fca58415420>, <mpyc.sectypes.ArraySecFld1(GF(2)) object at 0x7fca58414cd0>], [<mpyc.sectypes.ArraySecFld1(GF(2)) object at 0x7fca58414d30>, <mpyc.sectypes.ArraySecFld1(GF(2)) object at 0x7fca58415450>, <mpyc.sectypes.ArraySecFld1(GF(2)) object at 0x7fca584153f0>, <mpyc.sectypes.ArraySecFld1(GF(2)) object at 0x7fca58415480>]]
check:  [0 0 1 1 0 0 0 1 0 1 0 1 0 0 0 0 0 1 0 1 1 0 0 0 0 1 0 1 1 0 1 0 0 0 1 1 0
 1 1 1 0 0 1 1 1 0 0 1 0 1 0 0 1 0 1 1 0 1 0 0 0 0 1 1 0 1 0 0 1 1 0 0 0 1
 0 0 1 0 1 1 0 1 0 1 0 1 1 1 0 0 1 1 0 0 1 0 0 0 1 1 0 0 0 0 0 1 0 0 0 0 0
 1 0 1 0 0 0 0 0 1 0 1 0 0 1 1 0 1 0 0 1 1 0 0 0 0 0 0 1 1 0 0 1 0 0 0 1 1
 0 0 0 0 0 0 1 1 0 0 1 0 0 1 0 0 0 1 1 1 0 1 0 1 0 1 0 1 0 1 0 1 0 1 1 1 0
 0 1 1 0 1 0 1 0 0 1 1 1 0 0 0 0 1 0 1 1 0 0 0 0 1 0 1 0 0 1 1 0 1 0 1 1 0
 0 0 0 1 0 0 1 1 1 1 0 1 0 0 1 1 1 1 0 0 1 1 0 0 0 1 0 1 0 0 0 0 1 0 0 1 0
 1 0 0 0 0 0 1 0 1 0 1 0 1 0 1 0 0 0 0 1 0 0 1 0 1 0 1 1 1 0 0 1 1 1 0 0 0
 0 1 0 0 0 1 0 1 0 1 0 1 0 1 1 0 0 1 0 0 0 0 1 0 0 1 0 0 0 1 1 1 0 1 0 1 1
 0 0 0 0 1 0 1 0 1 1 1 0 1 0 1 1 0 0 1 0 1 0 0 1 0 1 1 0 1 0 0 0 1 1 0 0 1
 0 1 1 0 1 0 0 0 1 1 0 1 1 0 0 1 0 0 0 1 1 1 0 1 0 0 1 0 0 0 0 1 0 0 0 0 1
 1 0 0 1 1 0 0 1 1 0 1 0 1 0 0 1 0 0 1 0 0 1 1 1 0 0 1 0 1 0 0 0 0 0 0 1 1
 0 0 0 0 0 0 1 1 0 0 0 1 0 1 0 0 0 1 1 1 0 0 1 1 0 1 1 1 0 1 0 1 1 0 0 0 0
 0 1 1 0 1 1 1 0 1 0 1 0 0 1 1]
check:  []
2024-02-18 01:59:30,476 Unhandled exception in event loop
Traceback (most recent call last):
  File "/usr/lib/python3.10/asyncio/events.py", line 80, in _run
    self._context.run(self._callback, *self._args)
  File "/home/devifaustine/.local/lib/python3.10/site-packages/mpyc/asyncoro.py", line 475, in <lambda>
    task.add_done_callback(lambda t: _reconcile(decl, t))
  File "/home/devifaustine/.local/lib/python3.10/site-packages/mpyc/asyncoro.py", line 399, in _reconcile
    givn = task.result()
  File "/home/devifaustine/.local/lib/python3.10/site-packages/mpyc/asyncoro.py", line 327, in _wrap_in_coro
    return await awaitable
  File "/home/devifaustine/.local/lib/python3.10/site-packages/mpyc/asyncoro.py", line 315, in __await__
    val = self.coro.send(None)
  File "/home/devifaustine/.local/lib/python3.10/site-packages/mpyc/runtime.py", line 463, in _distribute
    y = [[field.array(unmarshal(r), check=False).reshape(shape)] for r in shares]
  File "/home/devifaustine/.local/lib/python3.10/site-packages/mpyc/runtime.py", line 463, in <listcomp>
    y = [[field.array(unmarshal(r), check=False).reshape(shape)] for r in shares]
  File "/home/devifaustine/.local/lib/python3.10/site-packages/mpyc/finfields.py", line 1287, in reshape
    return type(self)(self.value.reshape(*args, **kwargs), check=False)
ValueError: cannot reshape array of size 280 into shape (496,)
here's your payload:  (b'C57ADB2ONRXOPQ8G4HODWLEJC8OKU4PAx82Oxd7xe9<x16xcexd4)xeerS1x04x17x110x99xc4x9aXGx9d=x89x06$~x08_xb5xc8', b'H5IZJFFALI1TL8EU7ESB5BSFI0LTTT2UBPHFHTD0BR621F0B20Y48LBIEO432YY1C57ADB2ONRXOPQ8G4HODWLEJC8OKU4PAx82Oxd7xe9<x16xcexd4)xeerS1x04x17x110x99xc4x9aXGx9d=x89x06$~x08_xb5xc8')
The given input is a secret key!
here's the payload:  [<mpyc.sectypes.ArraySecFld1(GF(2)) object at 0x7f6b2329bb50>, <mpyc.sectypes.ArraySecFld1(GF(2)) object at 0x7f6b17703190>, <mpyc.sectypes.ArraySecFld1(GF(2)) object at 0x7f6b17703160>, <mpyc.sectypes.ArraySecFld1(GF(2)) object at 0x7f6b17702fb0>]
here's the inputs:  [[<mpyc.sectypes.ArraySecFld1(GF(2)) object at 0x7f6b17738c70>, <mpyc.sectypes.ArraySecFld1(GF(2)) object at 0x7f6b17738cd0>, <mpyc.sectypes.ArraySecFld1(GF(2)) object at 0x7f6b17738d00>, <mpyc.sectypes.ArraySecFld1(GF(2)) object at 0x7f6b17738d30>], [<mpyc.sectypes.ArraySecFld1(GF(2)) object at 0x7f6b17738ca0>, <mpyc.sectypes.ArraySecFld1(GF(2)) object at 0x7f6b17738d90>, <mpyc.sectypes.ArraySecFld1(GF(2)) object at 0x7f6b17738dc0>, <mpyc.sectypes.ArraySecFld1(GF(2)) object at 0x7f6b17738df0>]]
check:  [0 1 1 0 0 0 1 0 0 0 1 0 0 1 1 1 0 1 0 0 1 0 0 0 0 0 1 1 0 1 0 1 0 1 0 0 1
 0 0 1 0 1 0 1 1 0 1 0 0 1 0 0 1 0 1 0 0 1 0 0 0 1 1 0 0 1 0 0 0 1 1 0 0 1
 0 0 0 0 0 1 0 1 0 0 1 1 0 0 0 1 0 0 1 0 0 1 0 0 1 1 0 0 0 1 0 1 0 1 0 1 0
 0 0 1 0 0 1 1 0 0 0 0 1 1 1 0 0 0 0 1 0 0 0 1 0 1 0 1 0 1 0 1 0 1 0 0 1 1
 0 1 1 1 0 1 0 0 0 1 0 1 0 1 0 1 0 0 1 1 0 1 0 0 0 0 1 0 0 0 1 1 0 1 0 1 0
 1 0 0 0 0 1 0 0 1 0 1 0 0 1 1 0 1 0 0 0 1 1 0 0 1 0 0 1 0 0 1 0 0 1 1 0 0
 0 0 0 1 0 0 1 1 0 0 0 1 0 1 0 1 0 0 0 1 0 1 0 1 0 0 0 1 0 1 0 1 0 0 0 0 1
 1 0 0 1 0 0 1 0 1 0 1 0 1 0 0 1 0 0 1 1 1]
2024-02-18 01:59:30,476 Unhandled exception in event loop
Traceback (most recent call last):
  File "/usr/lib/python3.10/asyncio/events.py", line 80, in _run
    self._context.run(self._callback, *self._args)
  File "/home/devifaustine/.local/lib/python3.10/site-packages/mpyc/asyncoro.py", line 475, in <lambda>
    task.add_done_callback(lambda t: _reconcile(decl, t))
  File "/home/devifaustine/.local/lib/python3.10/site-packages/mpyc/asyncoro.py", line 399, in _reconcile
    givn = task.result()
  File "/home/devifaustine/.local/lib/python3.10/site-packages/mpyc/asyncoro.py", line 327, in _wrap_in_coro
    return await awaitable
  File "/home/devifaustine/.local/lib/python3.10/site-packages/mpyc/asyncoro.py", line 315, in __await__
    val = self.coro.send(None)
  File "/home/devifaustine/.local/lib/python3.10/site-packages/mpyc/runtime.py", line 463, in _distribute
    y = [[field.array(unmarshal(r), check=False).reshape(shape)] for r in shares]
  File "/home/devifaustine/.local/lib/python3.10/site-packages/mpyc/runtime.py", line 463, in <listcomp>
    y = [[field.array(unmarshal(r), check=False).reshape(shape)] for r in shares]
  File "/home/devifaustine/.local/lib/python3.10/site-packages/mpyc/finfields.py", line 1287, in reshape
    return type(self)(self.value.reshape(*args, **kwargs), check=False)
ValueError: cannot reshape array of size 496 into shape (280,)
Traceback (enclosing MPyC coroutine call):
Traceback (enclosing MPyC coroutine call):
