2024-03-03 00:14:05,870 Start MPyC runtime v0.9
2024-03-03 00:14:05,877 Start MPyC runtime v0.9
2024-03-03 00:14:05,918 All 2 parties connected.
Give your input here: 2024-03-03 00:14:05,918 All 2 parties connected.
Give your input here: here's your payload:  (b'V5H0VNF7B74NTPIVTVUUZEXJDSHHX4XHxadWxd5?[x98xdex8dxb8xa0xc4  xda&)x04bxbbY5x8axb1x19x1fxb5x11x97xebvxccx83', b'FJWNXPLCKL2TCRRLYS34JTAJI2F3T1CEZVCPJ8MA6HGSRWKI1F1EVXE1VUQUDE18V5H0VNF7B74NTPIVTVUUZEXJDSHHX4XHxadWxd5?[x98xdex8dxb8xa0xc4  xda&)x04bxbbY5x8axb1x19x1fxb5x11x97xebvxccx83')
The given input is a secret key!
Give the other input here: here's your payload:  WQ4UA8EACZ4A6QU7UZEYOPGUM9DDQ9B8R4CABYSXDN9VGMR3J7IR7FW8IAMAMJAJ
The given input ihere's the payload:  [<mpyc.sectypes.ArraySecFld1(GF(2)) object at 0x7f85696939a0>, <mpyc.sectypes.ArraySecFld1(GF(2)) object at 0x7f8562b91e70>, <mpyc.sectypes.ArraySecFld1(GF(2)) object at 0x7f8562b90f70>, <mpyc.sectypes.ArraySecFld1(GF(2)) object at 0x7f8562b92470>]
here's the inputs:  [[<mpyc.sectypes.ArraySecFld1(GF(2)) object at 0x7f8562b93f40>, <mpyc.sectypes.ArraySecFld1(GF(2)) object at 0x7f8562b93fa0>, <mpyc.sectypes.ArraySecFld1(GF(2)) object at 0x7f8562b93fd0>, <mpyc.sectypes.ArraySecFld1(GF(2)) object at 0x7f8562944040>], [<mpyc.sectypes.ArraySecFld1(GF(2)) object at 0x7f8562b93f70>, <mpyc.sectypes.ArraySecFld1(GF(2)) object at 0x7f85629440a0>, <mpyc.sectypes.ArraySecFld1(GF(2)) object at 0x7f85629440d0>, <mpyc.sectypes.ArraySecFld1(GF(2)) object at 0x7f8562944100>]]

Signing process begins now...
sign started
message digested.
id:  505
id:  19
fors signature generated.
FORS signature generated.
compute roots fors
.
.
.
.
.
.
.
.
.
.
.
.
.
.
.
.
.
.
.
.
.
.
.
.
.
Error during signing process. Try Again!
2024-03-03 00:22:18,715 Stop MPyC -- elapsed time: 0:08:34.508|bytes sent: 673
here's the payload:  [<mpyc.sectypes.ArraySecFld1(GF(2)) object at 0x7f857534f9a0>, <mpyc.sectypes.ArraySecFld1(GF(2)) object at 0x7f857534f880>, <mpyc.sectypes.ArraySecFld1(GF(2)) object at 0x7f856e8635e0>, <mpyc.sectypes.ArraySecFld1(GF(2)) object at 0x7f856e863580>]
here's the inputs:  [[<mpyc.sectypes.ArraySecFld1(GF(2)) object at 0x7f856e863670>, <mpyc.sectypes.ArraySecFld1(GF(2)) object at 0x7f856e8636d0>, <mpyc.sectypes.ArraySecFld1(GF(2)) object at 0x7f856e863700>, <mpyc.sectypes.ArraySecFld1(GF(2)) object at 0x7f856e863730>], [<mpyc.sectypes.ArraySecFld1(GF(2)) object at 0x7f856e8636a0>, <mpyc.sectypes.ArraySecFld1(GF(2)) object at 0x7f856e863790>, <mpyc.sectypes.ArraySecFld1(GF(2)) object at 0x7f856e8637c0>, <mpyc.sectypes.ArraySecFld1(GF(2)) object at 0x7f856e8637f0>]]

Signing process begins now...
sign started
message digested.
id:  168
id:  205
fors signature generated.
FORS signature generated.
compute roots fors
.
.
.
.
.
.
.
.
.
.
.
.
.
.
.
.
.
.
.
.
.
.
.
.
.
Error during signing process. Try Again!
2024-03-03 00:22:20,055 Stop MPyC -- elapsed time: 0:08:35.848|bytes sent: 673
2024-03-03 00:22:20,060 Unhandled exception in event loop
Traceback (most recent call last):
  File "/home/codespace/.python/current/lib/python3.10/asyncio/events.py", line 80, in _run
    self._context.run(self._callback, *self._args)
  File "/home/codespace/.python/current/lib/python3.10/site-packages/mpyc/asyncoro.py", line 431, in <lambda>
    task.add_done_callback(lambda t: _reconcile(decl, t))
  File "/home/codespace/.python/current/lib/python3.10/site-packages/mpyc/asyncoro.py", line 355, in _reconcile
    givn = task.result()
  File "/home/codespace/.python/current/lib/python3.10/site-packages/mpyc/asyncoro.py", line 283, in _wrap_in_coro
    return await awaitable
  File "/home/codespace/.python/current/lib/python3.10/site-packages/mpyc/asyncoro.py", line 271, in __await__
    val = self.coro.send(None)
  File "/home/codespace/.python/current/lib/python3.10/site-packages/mpyc/runtime.py", line 504, in output
    field = x[0].field
AttributeError: 'NoneType' object has no attribute 'field'
2024-03-03 00:22:20,060 Unhandled exception in event loop
Traceback (most recent call last):
  File "/home/codespace/.python/current/lib/python3.10/asyncio/events.py", line 80, in _run
    self._context.run(self._callback, *self._args)
  File "/home/codespace/.python/current/lib/python3.10/site-packages/mpyc/asyncoro.py", line 431, in <lambda>
    task.add_done_callback(lambda t: _reconcile(decl, t))
  File "/home/codespace/.python/current/lib/python3.10/site-packages/mpyc/asyncoro.py", line 355, in _reconcile
    givn = task.result()
  File "/home/codespace/.python/current/lib/python3.10/site-packages/mpyc/asyncoro.py", line 283, in _wrap_in_coro
    return await awaitable
  File "/home/codespace/.python/current/lib/python3.10/site-packages/mpyc/asyncoro.py", line 271, in __await__
    val = self.coro.send(None)
  File "/home/codespace/.python/current/lib/python3.10/site-packages/mpyc/runtime.py", line 504, in output
    field = x[0].field
AttributeError: 'NoneType' object has no attribute 'field'
Traceback (enclosing MPyC coroutine call):
Traceback (enclosing MPyC coroutine call):
tateError: invalid state
2024-03-03 00:14:22,977 Unhandled exception in event loop
Traceback (most recent call last):
  File "/home/codespace/.python/current/lib/python3.10/asyncio/events.py", line 80, in _run
    self._context.run(self._callback, *self._args)
  File "/home/codespace/.python/current/lib/python3.10/site-packages/mpyc/asyncoro.py", line 431, in <lambda>
    task.add_done_callback(lambda t: _reconcile(decl, t))
  File "/home/codespace/.python/current/lib/python3.10/site-packages/mpyc/asyncoro.py", line 355, in _reconcile
    givn = task.result()
  File "/home/codespace/.python/current/lib/python3.10/site-packages/mpyc/asyncoro.py", line 283, in _wrap_in_coro
    return await awaitable
  File "/home/codespace/.python/current/lib/python3.10/site-packages/mpyc/asyncoro.py", line 271, in __await__
    val = self.coro.send(None)
  File "/home/codespace/.python/current/lib/python3.10/site-packages/mpyc/runtime.py", line 452, in _distribute
    y = [[field.array(unmarshal(r), check=False).reshape(shape) for r in shares]]
  File "/home/codespace/.python/current/lib/python3.10/site-packages/mpyc/runtime.py", line 452, in <listcomp>
    y = [[field.array(unmarshal(r), check=False).reshape(shape) for r in shares]]
  File "/home/codespace/.python/current/lib/python3.10/site-packages/mpyc/finfields.py", line 1289, in reshape
    return type(self)(self.value.reshape(*args, **kwargs), check=False)
ValueError: cannot reshape array of size 256 into shape (512,)
Traceback (enclosing MPyC coroutine call):
