2024-03-03 02:34:45,363 Start MPyC runtime v0.9.9
2024-03-03 02:34:45,399 Start MPyC runtime v0.9.9
2024-03-03 02:34:45,469 All 2 parties connected.
2024-03-03 02:34:45,469 All 2 parties connected.
Give your input here: Give your input here: here's your payload:  (b'3SXN51TGYV7G53HMMF6K80BD1K9MQ8BDx1dxb1xf4xd1x93xa4xebx12Sxbc@xc7xe7x91x07xc7)xa4x8dxfdx87wVax1dx13xfbxd61eUx9e', b'3BZIMUJLZ7MQQAX4D5KP3JC8TI8ZPMUVYZ3VV56VBU9QSOHHKQ0KUB03HMJIX2L03SXN51TGYV7G53HMMF6K80BD1K9MQ8BDx1dxb1xf4xd1x93xa4xebx12Sxbc@xc7xe7x91x07xc7)xa4x8dxfdx87wVax1dx13xfbxd61eUx9e')
The given input is a secret key!
Give the other input here: here's your payload:  WKE8AM1EJC0HH2TDNLUADURWUMVW4JLQKEABHG9IWJSSV8W8ZRXBHUCYZHEK3EIXXK0K
The given input is a message!
Give the other input here: here's the payload:  [<mpyc.sectypes.ArraySecFld1(GF(2)) object at 0x7f6a37eaf0d0>, <mpyc.sectypes.ArraySecFld1(GF(2)) object at 0x7f6a2c3ae140>, <mpyc.sectypes.ArraySecFld1(GF(2)) object at 0x7f6a2c3ae110>, <mpyc.sectypes.ArraySecFld1(GF(2)) object at 0x7f6a2c3ad7e0>]
here's the inputs:  [[<mpyc.sectypes.ArraySecFld1(GF(2)) object at 0x7f6a2c3878b0>, <mpyc.sectypes.ArraySecFld1(GF(2)) object at 0x7f6a2c387f10>, <mpyc.sectypes.ArraySecFld1(GF(2)) object at 0x7f6a2c387fd0>, <mpyc.sectypes.ArraySecFld1(GF(2)) object at 0x7f6a2c387f40>], [<mpyc.sectypes.ArraySecFld1(GF(2)) object at 0x7f6a2c387850>, <mpyc.sectypes.ArraySecFld1(GF(2)) object at 0x7f6a2c387fa0>, <mpyc.sectypes.ArraySecFld1(GF(2)) object at 0x7f6a2c387ee0>, <mpyc.sectypes.ArraySecFld1(GF(2)) object at 0x7f6a2c387a00>]]

Signing process begins now...
sign started
The length of the message and secret key is wrong! Please restart the function!
2024-03-03 02:34:57,350 Unhandled exception in event loop
Traceback (most recent call last):
  File "/usr/lib/python3.10/asyncio/events.py", line 80, in _run
    self._context.run(self._callback, *self._args)
  File "/home/devifaustine/.local/lib/python3.10/site-packages/mpyc/asyncoro.py", line 461, in <lambda>
    task.add_done_callback(lambda t: _reconcile(decl, t))
  File "/home/devifaustine/.local/lib/python3.10/site-packages/mpyc/asyncoro.py", line 385, in _reconcile
    givn = task.result()
  File "/home/devifaustine/.local/lib/python3.10/site-packages/mpyc/asyncoro.py", line 313, in _wrap_in_coro
    return await awaitable
  File "/home/devifaustine/.local/lib/python3.10/site-packages/mpyc/asyncoro.py", line 301, in __await__
    val = self.coro.send(None)
  File "/home/devifaustine/.local/lib/python3.10/site-packages/mpyc/runtime.py", line 488, in _distribute
    y = [[field.array(unmarshal(r), check=False).reshape(shape)] for r in shares]
  File "/home/devifaustine/.local/lib/python3.10/site-packages/mpyc/runtime.py", line 488, in <listcomp>
    y = [[field.array(unmarshal(r), check=False).reshape(shape)] for r in shares]
  File "/home/devifaustine/.local/lib/python3.10/site-packages/mpyc/finfields.py", line 1287, in reshape
    return type(self)(self.value.reshape(*args, **kwargs), check=False)
ValueError: cannot reshape array of size 544 into shape (256,)
Traceback (enclosing MPyC coroutine call):
here's the payload:  [<mpyc.sectypes.ArraySecFld1(GF(2)) object at 0x7f4bc14af0d0>, <mpyc.sectypes.ArraySecFld1(GF(2)) object at 0x7f4bb58cbd90>, <mpyc.sectypes.ArraySecFld1(GF(2)) object at 0x7f4bb58cbc70>, <mpyc.sectypes.ArraySecFld1(GF(2)) object at 0x7f4bb58cbac0>]
here's the inputs:  [[<mpyc.sectypes.ArraySecFld1(GF(2)) object at 0x7f4bb58cba60>, <mpyc.sectypes.ArraySecFld1(GF(2)) object at 0x7f4bb58cbeb0>, <mpyc.sectypes.ArraySecFld1(GF(2)) object at 0x7f4bb58cb6a0>, <mpyc.sectypes.ArraySecFld1(GF(2)) object at 0x7f4bb58cb520>], [<mpyc.sectypes.ArraySecFld1(GF(2)) object at 0x7f4bb58cbaf0>, <mpyc.sectypes.ArraySecFld1(GF(2)) object at 0x7f4bb58cb4f0>, <mpyc.sectypes.ArraySecFld1(GF(2)) object at 0x7f4bb58f1990>, <mpyc.sectypes.ArraySecFld1(GF(2)) object at 0x7f4bb58f17e0>]]

Signing process begins now...
sign started
message digested.
id:  348
id:  259
id:  132
id:  287
id:  282
id:  212
id:  343
id:  27
fors signature generated.
FORS signature generated.
compute roots fors
.
.
.
.
.
.
.
.
.
.
.
.
.
.
.
.
.
.
.
.
.
.
.
.
.
Error during signing process. Try Again!
2024-03-03 02:34:58,711 Exception in callback _SelectorSocketTransport._call_connection_lost(None)
handle: <Handle _SelectorSocketTransport._call_connection_lost(None)>
Traceback (most recent call last):
  File "/usr/lib/python3.10/asyncio/events.py", line 80, in _run
    self._context.run(self._callback, *self._args)
  File "/usr/lib/python3.10/asyncio/selector_events.py", line 984, in _call_connection_lost
    super()._call_connection_lost(exc)
  File "/usr/lib/python3.10/asyncio/selector_events.py", line 742, in _call_connection_lost
    self._protocol.connection_lost(exc)
  File "/home/devifaustine/.local/lib/python3.10/site-packages/mpyc/asyncoro.py", line 134, in connection_lost
    rt.parties[rt.pid].protocol.set_result(None)
asyncio.exceptions.InvalidStateError: invalid state
2024-03-03 02:34:59,513 Unhandled exception in event loop
Traceback (most recent call last):
  File "/usr/lib/python3.10/asyncio/events.py", line 80, in _run
    self._context.run(self._callback, *self._args)
  File "/home/devifaustine/.local/lib/python3.10/site-packages/mpyc/asyncoro.py", line 461, in <lambda>
    task.add_done_callback(lambda t: _reconcile(decl, t))
  File "/home/devifaustine/.local/lib/python3.10/site-packages/mpyc/asyncoro.py", line 385, in _reconcile
    givn = task.result()
  File "/home/devifaustine/.local/lib/python3.10/site-packages/mpyc/asyncoro.py", line 313, in _wrap_in_coro
    return await awaitable
  File "/home/devifaustine/.local/lib/python3.10/site-packages/mpyc/asyncoro.py", line 301, in __await__
    val = self.coro.send(None)
  File "/home/devifaustine/.local/lib/python3.10/site-packages/mpyc/runtime.py", line 488, in _distribute
    y = [[field.array(unmarshal(r), check=False).reshape(shape)] for r in shares]
  File "/home/devifaustine/.local/lib/python3.10/site-packages/mpyc/runtime.py", line 488, in <listcomp>
    y = [[field.array(unmarshal(r), check=False).reshape(shape)] for r in shares]
  File "/home/devifaustine/.local/lib/python3.10/site-packages/mpyc/finfields.py", line 1287, in reshape
    return type(self)(self.value.reshape(*args, **kwargs), check=False)
ValueError: cannot reshape array of size 256 into shape (544,)
Traceback (enclosing MPyC coroutine call):
